## 循环与迭代

- **while**：`while (condition) statement` 只要 condition 为 true，语句会一直执行
- **do...while (condition)**：先执行一次 do 后面语句，当 while 中 condition 为 true 时，继续执行 do 语句，如果 condition 为 false 时，则不执行了
- for** 循环：
  - 表达式 `for ([initialExpression]; [condition]; [incrementExpression]) statement`
  - 循环会一直重复执行，直到指定的循环条件 condition 为 false
- **for...in** 循环：一个指定的变量来循环一个对象所有可枚举的属性，这个变量指的是属性名
- **for...of** 语句：
  - 在可迭代对象（包括 Array、String、Map、Set、arguments 等）中属性循环
  - ```for (variable of iterable) {//statements}```，variable 指的是元素值
- **break** 语句：中止循环或 switch 语句
- **continue** 语句：跳过代码块的剩余部分并进入下一循环，在 while、do-while、for 语句中使用
- **return** 语句：函数内使用，返回某个值


while
```js
var count = 0;
while (count < 10) {
  console.log(count)
  count++
}
```


do...while
```js
var i = 0
do {
  i++
  console.log(i)
} while (i < 10);
```


for 循环
```js
var i, j, sum = 0;
for (i = 0, j = 10; i < 10; i++, j--) {
  sum += i * j
}
console.log(sum)
```


break 语句
```js
for (var i = 0; i < 10; i++) {
  if (i == 5) break;
  console.log(i)
}
```


for/in 循环
```js
var o = {x: 1, y: 2, z: 3}
for (key in o) {
  console.log(key) // x y z
};
```


for...of 循环：
for...in 循环遍历的结果是数组元素的下标，而 for...of 遍历的结果是元素的值：
```js
let arr = [3, 5, 7];
arr.foo = "hello";

for (let i in arr) {
   console.log(i); // 输出 "0", "1", "2", "foo"
}

for (let i of arr) {
   console.log(i); // 输出 "3", "5", "7"
}
```

## 捕捉错误

- ```throw``` 语句:
  - 当前函数的执行将被停止（throw之后的语句将不会执行），并且控制将被传递到调用堆栈中的第一个catch块。如果调用者函数中没有catch块，程序将会终止。
- ```try...catch...finally``` 语句：
  - catch：只有 try 抛出异常时，这里才会执行，这里可以处理异常，也可以忽略，这里还可以抛出新异常，
  - finally：无论 try 语句块否抛出异常，都会执行


throw 语句
```js
function factorial(x) {
  if (x < 0) throw new Error('x 不能为复数')
  var i, j, sum = 0;
  for (i = 0, j = 10; i < 10; i++, j--) {
    sum += i * j
  }
  return sum
}
factorial(-1)
```


try/catch/finally 语句
```js
try {
  console.log('try')
  throw new Error('发生异常了')
} catch (e) {
  console.log('catch...', e) // catch... Error: 发生异常了
} finally {
  console.log('我都会执行 finally')
}

// 从 finally 语句块返回
function fn() {
  try {
    throw new Error('发生异常了')
  } finally {
    return 1;
  }
}
fn() // 1


// 嵌套 try
try {
  try {
    throw new Error("oops");
  }
  finally {
    console.log("finally");
  }
}
catch (ex) {
  console.error("outer", ex.message);
}
// 输出：
// finally
// outer oops

// 任何给定的异常只会被离它最近的封闭 catch 块捕获一次。
try {
  try {
    throw new Error("oops");
  }
  catch (ex) {
    console.error("inner", ex.message);
    throw ex;
  }
  finally {
    console.log("finally");
  }
}
catch (ex) {
  console.error("outer", ex.message);
}
// 输出：
// inner opps
// finally
// outer oops
```